在项目代码中，有个函数有个返回值是一个cancel 函数以供其他函数调用，简化后大致如下：
```go
func makeCancel() func() {
	_, cancel := context.WithCancel(context.Background())
	return cancel
}
```

为了在 `cancel()` 函数被调用时打一句 log，以便知道其被调用了，对 makeCancel() 函数进行了如下修改：
```go
package main

import (
	"context"
	"log"
)

type M map[string]interface{}

func main() {
	cancel := makeCancel()
	cancel()
}

func makeCancel() func() {
	_, cancel := context.WithCancel(context.Background())
	cancel = func() {
		cancel()
		log.Println(111)
	}
	return cancel
}
```

改完后程序崩溃，报栈溢出：
```
runtime: goroutine stack exceeds 1000000000-byte limit
fatal error: stack overflow
```

如果将 `log.Println(111)` 与 `cancel()` 对调，则会一直打印无限个 111。简单的问题被复杂化，因为原程序是 GRPC 相关，所以还追踪半天 GRPC 源码看看是如何出现的递归调用。

后来突然一惊，这完全是自己作死啊，cancel定义的时候又调用了cancel，多么明显的递归调用！！
一定是习惯了 a = a+1 这样的赋值语句，函数也想这么赋值，但函数和变量是不一样的！切记！

将 `makeCancel` 函数进行以下修改就可以避免：

```go
func makeCancel() func() {
	_, cancel := context.WithCancel(context.Background())
	newCancel := func() {
		cancel()
		log.Println(111)
	}
	return newCancel
}
```
